Workbook

Sheet Data Saham
A1: Date | B1: IHSG | C1: BBCA | D1: BBRI | E1: BMRI | F1: BBNI | G1: TLKM | H1: ASII | I1: ICBP | J1: INDF | K1: ADRO | L1: ITMG | M1: ANTM | N1: MDKA | O1: PGAS | P1: TOWR | Q1: EXCL | R1: KLBF | S1: CPIN | T1: JPFA | U1: SMGR | V1: UNTR | W1: BRPT | X1: AKRA | Y1: AMRT | Z1: ACES | AA1: MAPI | AB1: GOTO | AC1: BUKA | AD1: SMRA | AE1: PWON | AF1: CTRA
A2: 45719 | B2: 6519.66 | C2: 8800 | D2: 3670 | E2: 4900 | F2: 4260 | G2: 2400 | H2: 4680 | I2: 10575 | J2: 7350 | K2: 2050 | L2: 24025 | M2: 1585 | N2: 1525 | O2: 1520 | P2: 555 | Q2: 2220 | R2: 1110 | S2: 4420 | T2: 2020 | U2: 2340 | V2: 22425 | W2: 820 | X2: 1235 | Y2: 2360 | Z2: 670 | AA2: 1420 | AB2: 80 | AC2: 139 | AD2: 386 | AE2: 380 | AF2: 820
A3: 45750 | B3: 6380.4 | C3: 8850 | D3: 3670 | E3: 4840 | F3: 4220 | G3: 2380 | H3: 4690 | I3: 10575 | J3: 7325 | K3: 1910 | L3: 23075 | M3: 1540 | N3: 1470 | O3: 1520 | P3: 535 | Q3: 2220 | R3: 1110 | S3: 4260 | T3: 2020 | U3: 2210 | V3: 22175 | W3: 800 | X3: 1210 | Y3: 2390 | Z3: 665 | AA3: 1380 | AB3: 77 | AC3: 133 | AD3: 372 | AE3: 380 | AF3: 810
A4: 45780 | B4: 6531.4 | C4: 9000 | D4: 3840 | E4: 4860 | F4: 4460 | G4: 2450 | H4: 4900 | I4: 10400 | J4: 7425 | K4: 1900 | L4: 23225 | M4: 1620 | N4: 1480 | O4: 1520 | P4: 545 | Q4: 2270 | R4: 1090 | S4: 4790 | T4: 2110 | U4: 2270 | V4: 23675 | W4: 795 | X4: 1205 | Y4: 2390 | Z4: 680 | AA4: 1425 | AB4: 82 | AC4: 135 | AD4: 374 | AE4: 392 | AF4: 835
A5: 45811 | B5: 6617.85 | C5: 8975 | D5: 3950 | E5: 4870 | F5: 4590 | G5: 2400 | H5: 4900 | I5: 10350 | J5: 7300 | K5: 2050 | L5: 23500 | M5: 1625 | N5: 1475 | O5: 1505 | P5: 535 | Q5: 2250 | R5: 1150 | S5: 4390 | T5: 2130 | U5: 2330 | V5: 24925 | W5: 815 | X5: 1280 | Y5: 2370 | Z5: 675 | AA5: 1435 | AB5: 82 | AC5: 143 | AD5: 382 | AE5: 410 | AF5: 870
A6: 45841 | B6: 6636 | C6: 8925 | D6: 3810 | E6: 4840 | F6: 4540 | G6: 2410 | H6: 4930 | I6: 10550 | J6: 7250 | K6: 2000 | L6: 23700 | M6: 1630 | N6: 1530 | O6: 1510 | P6: 535 | Q6: 2250 | R6: 1160 | S6: 4310 | T6: 2120 | U6: 2360 | V6: 24050 | W6: 820 | X6: 1305 | Y6: 2420 | Z6: 670 | AA6: 1455 | AB6: 86 | AC6: 138 | AD6: 388 | AE6: 414 | AF6: 880
A7: 45933 | B7: 6598.21 | C7: 8925 | D7: 3760 | E7: 4710 | F7: 4450 | G7: 2390 | H7: 4770 | I7: 10600 | J7: 7550 | K7: 1915 | L7: 23850 | M7: 1490 | N7: 1400 | O7: 1485 | P7: 525 | Q7: 2270 | R7: 1080 | S7: 4520 | T7: 2180 | U7: 2440 | V7: 23650 | W7: 810 | X7: 1290 | Y7: 2440 | Z7: 675 | AA7: 1480 | AB7: 85 | AC7: 138 | AD7: 388 | AE7: 408 | AF7: 865
A8: 45964 | B8: 6545.85 | C8: 8925 | D8: 3790 | E8: 4740 | F8: 4450 | G8: 2370 | H8: 4800 | I8: 10425 | J8: 7275 | K8: 1850 | L8: 23900 | M8: 1520 | N8: 1310 | O8: 1450 | P8: 510 | Q8: 2260 | R8: 1060 | S8: 4310 | T8: 2120 | U8: 2330 | V8: 23700 | W8: 800 | X8: 1280 | Y8: 2320 | Z8: 665 | AA8: 1465 | AB8: 80 | AC8: 134 | AD8: 382 | AE8: 398 | AF8: 840
A9: 45994 | B9: 6665.04 | C9: 9125 | D9: 3890 | E9: 4880 | F9: 4530 | G9: 2450 | H9: 4810 | I9: 10925 | J9: 7475 | K9: 1850 | L9: 23275 | M9: 1545 | N9: 1330 | O9: 1510 | P9: 510 | Q9: 2270 | R9: 1070 | S9: 4360 | T9: 2120 | U9: 2340 | V9: 23350 | W9: 795 | X9: 1305 | Y9: 2400 | Z9: 655 | AA9: 1560 | AB9: 83 | AC9: 133 | AD9: 388 | AE9: 398 | AF9: 845
A10: 03/13/2025 | B10: 6647.42 | C10: 8975 | D10: 3800 | E10: 4740 | F10: 4530 | G10: 2430 | H10: 4730 | I10: 11000 | J10: 7300 | K10: 1865 | L10: 23400 | M10: 1535 | N10: 1340 | O10: 1555 | P10: 515 | Q10: 2250 | R10: 1085 | S10: 4380 | T10: 2120 | U10: 2330 | V10: 23050 | W10: 800 | X10: 1175 | Y10: 2400 | Z10: 645 | AA10: 1495 | AB10: 81 | AC10: 131 | AD10: 390 | AE10: 394 | AF10: 835
A11: 03/14/2025 | B11: 6515.63 | C11: 8750 | D11: 3750 | E11: 4740 | F11: 4430 | G11: 2420 | H11: 4620 | I11: 10750 | J11: 7175 | K11: 1810 | L11: 23125 | M11: 1590 | N11: 1340 | O11: 1535 | P11: 505 | Q11: 2260 | R11: 1050 | S11: 4240 | T11: 2090 | U11: 2260 | V11: 22725 | W11: 780 | X11: 1140 | Y11: 2360 | Z11: 600 | AA11: 1500 | AB11: 80 | AC11: 130 | AD11: 396 | AE11: 388 | AF11: 830
A12: 03/17/2025 | B12: 6471.95 | C12: 8600 | D12: 3830 | E12: 4680 | F12: 4330 | G12: 2420 | H12: 4620 | I12: 10950 | J12: 7275 | K12: 1815 | L12: 22925 | M12: 1655 | N12: 1440 | O12: 1525 | P12: 520 | Q12: 2270 | R12: 1060 | S12: 4320 | T12: 2050 | U12: 2260 | V12: 23225 | W12: 775 | X12: 1125 | Y12: 2430 | Z12: 615 | AA12: 1460 | AB12: 79 | AC12: 134 | AD12: 400 | AE12: 384 | AF12: 850
A13: 03/18/2025 | B13: 6223.39 | C13: 8300 | D13: 3680 | E13: 4530 | F13: 4190 | G13: 2420 | H13: 4650 | I13: 10825 | J13: 7075 | K13: 1795 | L13: 22500 | M13: 1635 | N13: 1420 | O13: 1510 | P13: 515 | Q13: 2250 | R13: 1015 | S13: 4340 | T13: 1990 | U13: 2210 | V13: 22450 | W13: 655 | X13: 1085 | Y13: 2240 | Z13: 580 | AA13: 1340 | AB13: 83 | AC13: 132 | AD13: 384 | AE13: 372 | AF13: 805
A14: 03/19/2025 | B14: 6311.66 | C14: 8325 | D14: 3710 | E14: 4680 | F14: 4170 | G14: 2430 | H14: 4690 | I14: 10725 | J14: 7200 | K14: 1800 | L14: 22650 | M14: 1660 | N14: 1410 | O14: 1500 | P14: 520 | Q14: 2270 | R14: 1030 | S14: 4500 | T14: 1985 | U14: 2230 | V14: 22325 | W14: 670 | X14: 1095 | Y14: 2170 | Z14: 595 | AA14: 1330 | AB14: 82 | AC14: 137 | AD14: 400 | AE14: 380 | AF14: 810
A15: 03/20/2025 | B15: 6381.67 | C15: 8375 | D15: 3660 | E15: 4620 | F15: 4080 | G15: 2390 | H15: 4710 | I15: 10600 | J15: 7025 | K15: 1800 | L15: 22900 | M15: 1645 | N15: 1430 | O15: 1540 | P15: 520 | Q15: 2270 | R15: 1090 | S15: 4500 | T15: 1995 | U15: 2250 | V15: 22625 | W15: 675 | X15: 1100 | Y15: 2130 | Z15: 505 | AA15: 1285 | AB15: 81 | AC15: 144 | AD15: 398 | AE15: 370 | AF15: 790
A16: 03/21/2025 | B16: 6258.18 | C16: 7900 | D16: 3700 | E16: 4410 | F16: 3770 | G16: 2310 | H16: 4840 | I16: 10575 | J16: 6975 | K16: 1800 | L16: 22475 | M16: 1585 | N16: 1375 | O16: 1540 | P16: 525 | Q16: 2260 | R16: 1120 | S16: 4480 | T16: 1980 | U16: 2120 | V16: 22875 | W16: 700 | X16: 1100 | Y16: 1940 | Z16: 500 | AA16: 1250 | AB16: 81 | AC16: 142 | AD16: 386 | AE16: 352 | AF16: 735
A17: 03/24/2025 | B17: 6161.22 | C17: 7950 | D17: 3610 | E17: 4460 | F17: 3720 | G17: 2330 | H17: 4690 | I17: 10425 | J17: 6800 | K17: 1750 | L17: 21875 | M17: 1590 | N17: 1345 | O17: 1525 | P17: 505 | Q17: 2260 | R17: 1105 | S17: 4400 | T17: 1980 | U17: 2220 | V17: 22700 | W17: 655 | X17: 1095 | Y17: 1820 | Z17: 500 | AA17: 1260 | AB17: 80 | AC17: 140 | AD17: 378 | AE17: 338 | AF17: 720
A18: 03/25/2025 | B18: 6235.62 | C18: 8050 | D18: 3800 | E18: 4740 | F18: 3900 | G18: 2340 | H18: 4650 | I18: 10375 | J18: 6800 | K18: 1745 | L18: 22450 | M18: 1600 | N18: 1350 | O18: 1500 | P18: 505 | Q18: 2230 | R18: 1135 | S18: 4400 | T18: 1955 | U18: 2510 | V18: 22825 | W18: 645 | X18: 1135 | Y18: 1870 | Z18: 505 | AA18: 1305 | AB18: 79 | AC18: 137 | AD18: 380 | AE18: 340 | AF18: 745
A19: 03/26/2025 | B19: 6472.36 | C19: 8525 | D19: 4000 | E19: 5150 | F19: 4250 | G19: 2440 | H19: 4800 | I19: 10550 | J19: 6925 | K19: 1840 | L19: 22950 | M19: 1650 | N19: 1450 | O19: 1550 | P19: 525 | Q19: 2250 | R19: 1100 | S19: 4480 | T19: 2010 | U19: 2750 | V19: 23500 | W19: 680 | X19: 1105 | Y19: 2010 | Z19: 520 | AA19: 1325 | AB19: 83 | AC19: 143 | AD19: 392 | AE19: 348 | AF19: 770
A20: 03/27/2025 | B20: 6510.62 | C20: 8500 | D20: 4050 | E20: 5200 | F20: 4240 | G20: 2410 | H20: 4920 | I20: 10175 | J20: 7100 | K20: 1845 | L20: 22950 | M20: 1635 | N20: 1430 | O20: 1555 | P20: 505 | Q20: 2280 | R20: 1135 | S20: 4390 | T20: 2010 | U20: 2650 | V20: 23550 | W20: 710 | X20: 1095 | Y20: 2050 | Z20: 500 | AA20: 1350 | AB20: 83 | AC20: 143 | AD20: 394 | AE20: 340 | AF20: 750
A21: 45873 | B21: 5996.14 | C21: 7775 | D21: 3640 | E21: 4670 | F21: 4030 | G21: 2290 | H21: 4480 | I21: 9700 | J21: 7200 | K21: 1645 | L21: 21825 | M21: 1400 | N21: 1220 | O21: 1445 | P21: 460 | Q21: 2200 | R21: 1055 | S21: 3980 | T21: 1895 | U21: 2260 | V21: 20100 | W21: 645 | X21: 970 | Y21: 2030 | Z21: 450 | AA21: 1150 | AB21: 71 | AC21: 126 | AD21: 352 | AE21: 312 | AF21: 720
A22: 45904 | B22: 5967.99 | C22: 7925 | D22: 3630 | E22: 4710 | F22: 4040 | G22: 2320 | H22: 4620 | I22: 9575 | J22: 6675 | K22: 1650 | L22: 22775 | M22: 1475 | N22: 1040 | O22: 1490 | P22: 468 | Q22: 2250 | R22: 1105 | S22: 4050 | T22: 1880 | U22: 2090 | V22: 20550 | W22: 600 | X22: 900 | Y22: 2070 | Z22: 462 | AA22: 1100 | AB22: 67 | AC22: 124 | AD22: 352 | AE22: 312 | AF22: 745
A23: 45934 | B23: 6254.02 | C23: 8225 | D23: 3800 | E23: 5025 | F23: 4260 | G23: 2350 | H23: 4710 | I23: 10000 | J23: 7075 | K23: 1700 | L23: 23275 | M23: 1630 | N23: 1220 | O23: 1550 | P23: 515 | Q23: 2280 | R23: 1145 | S23: 4180 | T23: 1970 | U23: 2160 | V23: 21800 | W23: 655 | X23: 1100 | Y23: 2290 | Z23: 500 | AA23: 1275 | AB23: 76 | AC23: 129 | AD23: 366 | AE23: 328 | AF23: 795
A24: 45965 | B24: 6262.23 | C24: 8275 | D24: 3630 | E24: 5100 | F24: 4390 | G24: 2330 | H24: 4710 | I24: 9925 | J24: 6900 | K24: 1715 | L24: 23400 | M24: 1690 | N24: 1305 | O24: 1580 | P24: 510 | Q24: 2200 | R24: 1180 | S24: 4120 | T24: 1945 | U24: 2140 | V24: 21850 | W24: 665 | X24: 1050 | Y24: 2210 | Z24: 492 | AA24: 1305 | AB24: 77 | AC24: 130 | AD24: 368 | AE24: 330 | AF24: 790
A25: 04/14/2025 | B25: 6368.52 | C25: 8400 | D25: 3690 | E25: 4750 | F25: 4550 | G25: 2430 | H25: 4930 | I25: 10325 | J25: 7125 | K25: 1765 | L25: 24800 | M25: 1830 | N25: 1440 | O25: 1640 | P25: 525 | Q25: 2190 | R25: 1240 | S25: 4320 | T25: 2050 | U25: 2460 | V25: 22650 | W25: 695 | X25: 1075 | Y25: 2170 | Z25: 530 | AA25: 1360 | AB25: 80 | AC25: 131 | AD25: 382 | AE25: 352 | AF25: 840
A26: 04/15/2025 | B26: 6441.68 | C26: 8575 | D26: 3690 | E26: 4710 | F26: 4280 | G26: 2450 | H26: 4870 | I26: 10475 | J26: 7300 | K26: 1800 | L26: 24700 | M26: 1860 | N26: 1430 | O26: 1685 | P26: 525 | Q26: 2170 | R26: 1195 | S26: 4250 | T26: 2000 | U26: 2500 | V26: 22825 | W26: 705 | X26: 1050 | Y26: 2080 | Z26: 496 | AA26: 1365 | AB26: 79 | AC26: 131 | AD26: 388 | AE26: 352 | AF26: 845
A27: 04/16/2025 | B27: 6400.05 | C27: 8475 | D27: 3650 | E27: 4630 | F27: 4100 | G27: 2480 | H27: 4780 | I27: 10250 | J27: 7400 | K27: 1800 | L27: 24600 | M27: 1925 | N27: 1415 | O27: 1670 | P27: 515 | Q27: 2190 | R27: 1255 | S27: 4260 | T27: 2050 | U27: 2450 | V27: 22225 | W27: 730 | X27: 1045 | Y27: 1955 | Z27: 488 | AA27: 1365 | AB27: 80 | AC27: 129 | AD27: 378 | AE27: 348 | AF27: 815
A28: 04/17/2025 | B28: 6438.27 | C28: 8500 | D28: 3640 | E28: 4600 | F28: 4040 | G28: 2550 | H28: 4750 | I28: 10600 | J28: 7300 | K28: 1800 | L28: 24800 | M28: 1945 | N28: 1645 | O28: 1675 | P28: 535 | Q28: 2180 | R28: 1200 | S28: 4240 | T28: 2010 | U28: 2450 | V28: 22225 | W28: 765 | X28: 1050 | Y28: 1960 | Z28: 472 | AA28: 1370 | AB28: 80 | AC28: 135 | AD28: 388 | AE28: 356 | AF28: 840
A29: 04/21/2025 | B29: 6445.97 | C29: 8300 | D29: 3620 | E29: 4610 | F29: 3990 | G29: 2570 | H29: 4790 | I29: 10550 | J29: 7350 | K29: 1805 | L29: 22175 | M29: 2090 | N29: 1695 | O29: 1680 | P29: 535 | Q29: 2120 | R29: 1225 | S29: 4160 | T29: 1905 | U29: 2370 | V29: 22900 | W29: 765 | X29: 1075 | Y29: 1935 | Z29: 478 | AA29: 1380 | AB29: 79 | AC29: 140 | AD29: 392 | AE29: 352 | AF29: 845
A30: 04/22/2025 | B30: 6538.27 | C30: 8500 | D30: 3630 | E30: 4720 | F30: 4010 | G30: 2550 | H30: 4740 | I30: 10475 | J30: 7200 | K30: 1880 | L30: 22325 | M30: 2190 | N30: 1665 | O30: 1675 | P30: 540 | Q30: 2100 | R30: 1200 | S30: 4050 | T30: 1715 | U30: 2540 | V30: 23025 | W30: 770 | X30: 1105 | Y30: 1910 | Z30: 484 | AA30: 1380 | AB30: 79 | AC30: 138 | AD30: 404 | AE30: 366 | AF30: 845
A31: 04/23/2025 | B31: 6634.38 | C31: 8725 | D31: 3760 | E31: 4900 | F31: 4150 | G31: 2630 | H31: 4820 | I31: 10700 | J31: 7350 | K31: 1850 | L31: 22300 | M31: 2070 | N31: 1570 | O31: 1715 | P31: 550 | Q31: 2110 | R31: 1280 | S31: 4190 | T31: 1720 | U31: 2550 | V31: 23050 | W31: 775 | X31: 1135 | Y31: 2000 | Z31: 505 | AA31: 1355 | AB31: 80 | AC31: 140 | AD31: 412 | AE31: 368 | AF31: 855
A32: 04/24/2025 | B32: 6613.48 | C32: 8475 | D32: 3730 | E32: 4890 | F32: 4170 | G32: 2630 | H32: 4770 | I32: 11000 | J32: 7250 | K32: 1875 | L32: 22050 | M32: 2150 | N32: 1610 | O32: 1770 | P32: 545 | Q32: 2090 | R32: 1265 | S32: 4280 | T32: 1730 | U32: 2530 | V32: 23050 | W32: 765 | X32: 1195 | Y32: 2030 | Z32: 500 | AA32: 1335 | AB32: 80 | AC32: 140 | AD32: 416 | AE32: 364 | AF32: 870
A33: 04/25/2025 | B33: 6678.92 | C33: 8600 | D33: 3740 | E33: 4900 | F33: 4200 | G33: 2600 | H33: 4860 | I33: 11000 | J33: 7475 | K33: 1880 | L33: 22100 | M33: 2140 | N33: 1680 | O33: 1725 | P33: 555 | Q33: 2100 | R33: 1240 | S33: 4420 | T33: 1780 | U33: 2600 | V33: 23100 | W33: 750 | X33: 1185 | Y33: 2090 | Z33: 525 | AA33: 1345 | AB33: 84 | AC33: 150 | AD33: 434 | AE33: 374 | AF33: 925
A34: 04/28/2025 | B34: 6722.97 | C34: 8775 | D34: 3840 | E34: 4920 | F34: 4190 | G34: 2560 | H34: 4890 | I34: 11000 | J34: 7425 | K34: 1900 | L34: 22075 | M34: 2130 | N34: 1660 | O34: 1710 | P34: 565 | Q34: 2100 | R34: 1260 | S34: 4460 | T34: 1885 | U34: 2570 | V34: 22900 | W34: 755 | X34: 1200 | Y34: 2040 | Z34: 515 | AA34: 1345 | AB34: 82 | AC34: 145 | AD34: 432 | AE34: 374 | AF34: 905
A35: 04/29/2025 | B35: 6749.08 | C35: 8725 | D35: 3850 | E35: 4940 | F35: 4140 | G35: 2590 | H35: 4800 | I35: 11250 | J35: 7500 | K35: 1900 | L35: 22050 | M35: 2180 | N35: 1720 | O35: 1720 | P35: 590 | Q35: 2130 | R35: 1260 | S35: 4440 | T35: 1845 | U35: 2560 | V35: 22675 | W35: 755 | X35: 1240 | Y35: 2090 | Z35: 545 | AA35: 1355 | AB35: 85 | AC35: 144 | AD35: 428 | AE35: 378 | AF35: 905
A36: 04/30/2025 | B36: 6766.79 | C36: 8825 | D36: 3850 | E36: 4890 | F36: 4180 | G36: 2640 | H36: 4800 | I36: 11350 | J36: 8000 | K36: 1900 | L36: 22000 | M36: 2170 | N36: 1670 | O36: 1685 | P36: 570 | Q36: 2150 | R36: 1365 | S36: 4730 | T36: 1820 | U36: 2610 | V36: 22700 | W36: 745 | X36: 1260 | Y36: 2160 | Z36: 535 | AA36: 1365 | AB36: 85 | AC36: 145 | AD36: 432 | AE36: 382 | AF36: 920
A37: 45693 | B37: 6815.73 | C37: 8975 | D37: 3880 | E37: 4960 | F37: 4200 | G37: 2680 | H37: 4790 | I37: 11000 | J37: 7700 | K37: 1885 | L37: 21950 | M37: 2290 | N37: 1690 | O37: 1635 | P37: 585 | Q37: 2220 | R37: 1315 | S37: 4740 | T37: 1750 | U37: 2540 | V37: 22775 | W37: 755 | X37: 1245 | Y37: 2120 | Z37: 520 | AA37: 1335 | AB37: 82 | AC37: 147 | AD37: 418 | AE37: 380 | AF37: 930
A38: 45782 | B38: 6831.95 | C38: 8975 | D38: 3860 | E38: 4980 | F38: 4210 | G38: 2700 | H38: 4780 | I38: 11200 | J38: 7600 | K38: 1860 | L38: 22050 | M38: 2320 | N38: 1680 | O38: 1630 | P38: 580 | Q38: 2200 | R38: 1390 | S38: 4650 | T38: 1745 | U38: 2550 | V38: 22800 | W38: 770 | X38: 1270 | Y38: 2180 | Z38: 525 | AA38: 1335 | AB38: 83 | AC38: 145 | AD38: 430 | AE38: 386 | AF38: 950
A39: 45813 | B39: 6898.2 | C39: 9025 | D39: 3880 | E39: 4980 | F39: 4180 | G39: 2680 | H39: 4750 | I39: 11275 | J39: 7525 | K39: 1875 | L39: 22275 | M39: 2540 | N39: 1780 | O39: 1620 | P39: 575 | Q39: 2180 | R39: 1410 | S39: 4800 | T39: 1765 | U39: 2550 | V39: 22875 | W39: 780 | X39: 1270 | Y39: 2280 | Z39: 525 | AA39: 1350 | AB39: 83 | AC39: 147 | AD39: 436 | AE39: 384 | AF39: 950
A40: 45843 | B40: 6926.23 | C40: 9075 | D40: 3910 | E40: 4950 | F40: 4160 | G40: 2620 | H40: 4830 | I40: 11075 | J40: 7750 | K40: 1900 | L40: 22350 | M40: 2750 | N40: 1855 | O40: 1635 | P40: 590 | Q40: 2180 | R40: 1405 | S40: 4850 | T40: 1795 | U40: 2510 | V40: 21750 | W40: 845 | X40: 1290 | Y40: 2310 | Z40: 545 | AA40: 1360 | AB40: 84 | AC40: 146 | AD40: 450 | AE40: 398 | AF40: 985
...

Sheet Return
A1: Date | B1: IHSG | C1: BBCA | D1: BBRI | E1: BMRI | F1: BBNI | G1: TLKM | H1: ASII | I1: ICBP | J1: INDF | K1: ADRO | L1: ITMG | M1: ANTM | N1: MDKA | O1: PGAS | P1: TOWR | Q1: EXCL | R1: KLBF | S1: CPIN | T1: JPFA | U1: SMGR | V1: UNTR | W1: BRPT | X1: AKRA | Y1: AMRT | Z1: ACES | AA1: MAPI | AB1: GOTO | AC1: BUKA | AD1: SMRA | AE1: PWON | AF1: CTRA
A2: 45719
A3: 45750 | B3: =('Data Saham'!B3-'Data Saham'!B2)/'Data Saham'!B2 -> -0.02136001 | C3: =('Data Saham'!C3-'Data Saham'!C2)/'Data Saham'!C2 -> 0.0056818182 | D3: =('Data Saham'!D3-'Data Saham'!D2)/'Data Saham'!D2 -> 0 | E3: =('Data Saham'!E3-'Data Saham'!E2)/'Data Saham'!E2 -> -0.012244898 | F3: =('Data Saham'!F3-'Data Saham'!F2)/'Data Saham'!F2 -> -0.0093896714 | G3: =('Data Saham'!G3-'Data Saham'!G2)/'Data Saham'!G2 -> -0.0083333333 | H3: =('Data Saham'!H3-'Data Saham'!H2)/'Data Saham'!H2 -> 0.0021367521 | I3: =('Data Saham'!I3-'Data Saham'!I2)/'Data Saham'!I2 -> 0 | ... AF3: =('Data Saham'!AF3-'Data Saham'!AF2)/'Data Saham'!AF2 -> -0.012195122
A4: 45780 | B4: =('Data Saham'!B4-'Data Saham'!B3)/'Data Saham'!B3 -> 0.023666228 | C4: =('Data Saham'!C4-'Data Saham'!C3)/'Data Saham'!C3 -> 0.016949153 | D4: =('Data Saham'!D4-'Data Saham'!D3)/'Data Saham'!D3 -> 0.046321526 | E4: =('Data Saham'!E4-'Data Saham'!E3)/'Data Saham'!E3 -> 0.0041322314 | F4: =('Data Saham'!F4-'Data Saham'!F3)/'Data Saham'!F3 -> 0.056872038 | G4: =('Data Saham'!G4-'Data Saham'!G3)/'Data Saham'!G3 -> 0.029411765 | H4: =('Data Saham'!H4-'Data Saham'!H3)/'Data Saham'!H3 -> 0.044776119 | I4: =('Data Saham'!I4-'Data Saham'!I3)/'Data Saham'!I3 -> -0.016548463 | ... AF4: =('Data Saham'!AF4-'Data Saham'!AF3)/'Data Saham'!AF3 -> 0.030864198
A5: 45811 | B5: =('Data Saham'!B5-'Data Saham'!B4)/'Data Saham'!B4 -> 0.01323606 | C5: =('Data Saham'!C5-'Data Saham'!C4)/'Data Saham'!C4 -> -0.0027777778 | D5: =('Data Saham'!D5-'Data Saham'!D4)/'Data Saham'!D4 -> 0.028645833 | E5: =('Data Saham'!E5-'Data Saham'!E4)/'Data Saham'!E4 -> 0.0020576132 | F5: =('Data Saham'!F5-'Data Saham'!F4)/'Data Saham'!F4 -> 0.029147982 | G5: =('Data Saham'!G5-'Data Saham'!G4)/'Data Saham'!G4 -> -0.020408163 | H5: =('Data Saham'!H5-'Data Saham'!H4)/'Data Saham'!H4 -> 0 | I5: =('Data Saham'!I5-'Data Saham'!I4)/'Data Saham'!I4 -> -0.0048076923 | ... AF5: =('Data Saham'!AF5-'Data Saham'!AF4)/'Data Saham'!AF4 -> 0.041916168
A6: 45841 | B6: =('Data Saham'!B6-'Data Saham'!B5)/'Data Saham'!B5 -> 0.0027425826 | C6: =('Data Saham'!C6-'Data Saham'!C5)/'Data Saham'!C5 -> -0.0055710306 | D6: =('Data Saham'!D6-'Data Saham'!D5)/'Data Saham'!D5 -> -0.035443038 | E6: =('Data Saham'!E6-'Data Saham'!E5)/'Data Saham'!E5 -> -0.0061601643 | F6: =('Data Saham'!F6-'Data Saham'!F5)/'Data Saham'!F5 -> -0.010893246 | G6: =('Data Saham'!G6-'Data Saham'!G5)/'Data Saham'!G5 -> 0.0041666667 | H6: =('Data Saham'!H6-'Data Saham'!H5)/'Data Saham'!H5 -> 0.006122449 | I6: =('Data Saham'!I6-'Data Saham'!I5)/'Data Saham'!I5 -> 0.019323671 | ... AF6: =('Data Saham'!AF6-'Data Saham'!AF5)/'Data Saham'!AF5 -> 0.011494253
A7: 45933 | B7: =('Data Saham'!B7-'Data Saham'!B6)/'Data Saham'!B6 -> -0.0056946956 | C7: =('Data Saham'!C7-'Data Saham'!C6)/'Data Saham'!C6 -> 0 | D7: =('Data Saham'!D7-'Data Saham'!D6)/'Data Saham'!D6 -> -0.01312336 | E7: =('Data Saham'!E7-'Data Saham'!E6)/'Data Saham'!E6 -> -0.026859504 | F7: =('Data Saham'!F7-'Data Saham'!F6)/'Data Saham'!F6 -> -0.019823789 | G7: =('Data Saham'!G7-'Data Saham'!G6)/'Data Saham'!G6 -> -0.0082987552 | H7: =('Data Saham'!H7-'Data Saham'!H6)/'Data Saham'!H6 -> -0.032454361 | I7: =('Data Saham'!I7-'Data Saham'!I6)/'Data Saham'!I6 -> 0.0047393365 | ... AF7: =('Data Saham'!AF7-'Data Saham'!AF6)/'Data Saham'!AF6 -> -0.017045455
A8: 45964 | B8: =('Data Saham'!B8-'Data Saham'!B7)/'Data Saham'!B7 -> -0.0079354855 | C8: =('Data Saham'!C8-'Data Saham'!C7)/'Data Saham'!C7 -> 0 | D8: =('Data Saham'!D8-'Data Saham'!D7)/'Data Saham'!D7 -> 0.0079787234 | E8: =('Data Saham'!E8-'Data Saham'!E7)/'Data Saham'!E7 -> 0.0063694268 | F8: =('Data Saham'!F8-'Data Saham'!F7)/'Data Saham'!F7 -> 0 | G8: =('Data Saham'!G8-'Data Saham'!G7)/'Data Saham'!G7 -> -0.0083682008 | H8: =('Data Saham'!H8-'Data Saham'!H7)/'Data Saham'!H7 -> 0.0062893082 | I8: =('Data Saham'!I8-'Data Saham'!I7)/'Data Saham'!I7 -> -0.016509434 | ... AF8: =('Data Saham'!AF8-'Data Saham'!AF7)/'Data Saham'!AF7 -> -0.028901734
A9: 45994 | B9: =('Data Saham'!B9-'Data Saham'!B8)/'Data Saham'!B8 -> 0.018208483 | C9: =('Data Saham'!C9-'Data Saham'!C8)/'Data Saham'!C8 -> 0.022408964 | D9: =('Data Saham'!D9-'Data Saham'!D8)/'Data Saham'!D8 -> 0.026385224 | E9: =('Data Saham'!E9-'Data Saham'!E8)/'Data Saham'!E8 -> 0.029535865 | F9: =('Data Saham'!F9-'Data Saham'!F8)/'Data Saham'!F8 -> 0.017977528 | G9: =('Data Saham'!G9-'Data Saham'!G8)/'Data Saham'!G8 -> 0.033755274 | H9: =('Data Saham'!H9-'Data Saham'!H8)/'Data Saham'!H8 -> 0.0020833333 | I9: =('Data Saham'!I9-'Data Saham'!I8)/'Data Saham'!I8 -> 0.047961631 | ... AF9: =('Data Saham'!AF9-'Data Saham'!AF8)/'Data Saham'!AF8 -> 0.005952381
A10: 03/13/2025 | B10: =('Data Saham'!B10-'Data Saham'!B9)/'Data Saham'!B9 -> -0.002643645 | C10: =('Data Saham'!C10-'Data Saham'!C9)/'Data Saham'!C9 -> -0.016438356 | D10: =('Data Saham'!D10-'Data Saham'!D9)/'Data Saham'!D9 -> -0.023136247 | E10: =('Data Saham'!E10-'Data Saham'!E9)/'Data Saham'!E9 -> -0.028688525 | F10: =('Data Saham'!F10-'Data Saham'!F9)/'Data Saham'!F9 -> 0 | G10: =('Data Saham'!G10-'Data Saham'!G9)/'Data Saham'!G9 -> -0.0081632653 | H10: =('Data Saham'!H10-'Data Saham'!H9)/'Data Saham'!H9 -> -0.016632017 | I10: =('Data Saham'!I10-'Data Saham'!I9)/'Data Saham'!I9 -> 0.0068649886 | ... AF10: =('Data Saham'!AF10-'Data Saham'!AF9)/'Data Saham'!AF9 -> -0.01183432
A11: 03/14/2025 | B11: =('Data Saham'!B11-'Data Saham'!B10)/'Data Saham'!B10 -> -0.019825737 | C11: =('Data Saham'!C11-'Data Saham'!C10)/'Data Saham'!C10 -> -0.025069638 | D11: =('Data Saham'!D11-'Data Saham'!D10)/'Data Saham'!D10 -> -0.013157895 | E11: =('Data Saham'!E11-'Data Saham'!E10)/'Data Saham'!E10 -> 0 | F11: =('Data Saham'!F11-'Data Saham'!F10)/'Data Saham'!F10 -> -0.022075055 | G11: =('Data Saham'!G11-'Data Saham'!G10)/'Data Saham'!G10 -> -0.0041152263 | H11: =('Data Saham'!H11-'Data Saham'!H10)/'Data Saham'!H10 -> -0.023255814 | I11: =('Data Saham'!I11-'Data Saham'!I10)/'Data Saham'!I10 -> -0.022727273 | ... AF11: =('Data Saham'!AF11-'Data Saham'!AF10)/'Data Saham'!AF10 -> -0.005988024
A12: 03/17/2025 | B12: =('Data Saham'!B12-'Data Saham'!B11)/'Data Saham'!B11 -> -0.0067038797 | C12: =('Data Saham'!C12-'Data Saham'!C11)/'Data Saham'!C11 -> -0.017142857 | D12: =('Data Saham'!D12-'Data Saham'!D11)/'Data Saham'!D11 -> 0.021333333 | E12: =('Data Saham'!E12-'Data Saham'!E11)/'Data Saham'!E11 -> -0.012658228 | F12: =('Data Saham'!F12-'Data Saham'!F11)/'Data Saham'!F11 -> -0.022573363 | G12: =('Data Saham'!G12-'Data Saham'!G11)/'Data Saham'!G11 -> 0 | H12: =('Data Saham'!H12-'Data Saham'!H11)/'Data Saham'!H11 -> 0 | I12: =('Data Saham'!I12-'Data Saham'!I11)/'Data Saham'!I11 -> 0.018604651 | ... AF12: =('Data Saham'!AF12-'Data Saham'!AF11)/'Data Saham'!AF11 -> 0.024096386
A13: 03/18/2025 | B13: =('Data Saham'!B13-'Data Saham'!B12)/'Data Saham'!B12 -> -0.038405736 | C13: =('Data Saham'!C13-'Data Saham'!C12)/'Data Saham'!C12 -> -0.034883721 | D13: =('Data Saham'!D13-'Data Saham'!D12)/'Data Saham'!D12 -> -0.039164491 | E13: =('Data Saham'!E13-'Data Saham'!E12)/'Data Saham'!E12 -> -0.032051282 | F13: =('Data Saham'!F13-'Data Saham'!F12)/'Data Saham'!F12 -> -0.032332564 | G13: =('Data Saham'!G13-'Data Saham'!G12)/'Data Saham'!G12 -> 0 | H13: =('Data Saham'!H13-'Data Saham'!H12)/'Data Saham'!H12 -> 0.0064935065 | I13: =('Data Saham'!I13-'Data Saham'!I12)/'Data Saham'!I12 -> -0.011415525 | ... AF13: =('Data Saham'!AF13-'Data Saham'!AF12)/'Data Saham'!AF12 -> -0.052941176
A14: 03/19/2025 | B14: =('Data Saham'!B14-'Data Saham'!B13)/'Data Saham'!B13 -> 0.014183588 | C14: =('Data Saham'!C14-'Data Saham'!C13)/'Data Saham'!C13 -> 0.0030120482 | D14: =('Data Saham'!D14-'Data Saham'!D13)/'Data Saham'!D13 -> 0.0081521739 | E14: =('Data Saham'!E14-'Data Saham'!E13)/'Data Saham'!E13 -> 0.033112583 | F14: =('Data Saham'!F14-'Data Saham'!F13)/'Data Saham'!F13 -> -0.0047732697 | G14: =('Data Saham'!G14-'Data Saham'!G13)/'Data Saham'!G13 -> 0.0041322314 | H14: =('Data Saham'!H14-'Data Saham'!H13)/'Data Saham'!H13 -> 0.0086021505 | I14: =('Data Saham'!I14-'Data Saham'!I13)/'Data Saham'!I13 -> -0.0092378753 | ... AF14: =('Data Saham'!AF14-'Data Saham'!AF13)/'Data Saham'!AF13 -> 0.0062111801
A15: 03/20/2025 | B15: =('Data Saham'!B15-'Data Saham'!B14)/'Data Saham'!B14 -> 0.011092169 | C15: =('Data Saham'!C15-'Data Saham'!C14)/'Data Saham'!C14 -> 0.006006006 | D15: =('Data Saham'!D15-'Data Saham'!D14)/'Data Saham'!D14 -> -0.013477089 | E15: =('Data Saham'!E15-'Data Saham'!E14)/'Data Saham'!E14 -> -0.012820513 | F15: =('Data Saham'!F15-'Data Saham'!F14)/'Data Saham'!F14 -> -0.021582734 | G15: =('Data Saham'!G15-'Data Saham'!G14)/'Data Saham'!G14 -> -0.016460905 | H15: =('Data Saham'!H15-'Data Saham'!H14)/'Data Saham'!H14 -> 0.0042643923 | I15: =('Data Saham'!I15-'Data Saham'!I14)/'Data Saham'!I14 -> -0.011655012 | ... AF15: =('Data Saham'!AF15-'Data Saham'!AF14)/'Data Saham'!AF14 -> -0.024691358
A16: 03/21/2025 | B16: =('Data Saham'!B16-'Data Saham'!B15)/'Data Saham'!B15 -> -0.019350734 | C16: =('Data Saham'!C16-'Data Saham'!C15)/'Data Saham'!C15 -> -0.056716418 | D16: =('Data Saham'!D16-'Data Saham'!D15)/'Data Saham'!D15 -> 0.010928962 | E16: =('Data Saham'!E16-'Data Saham'!E15)/'Data Saham'!E15 -> -0.045454545 | F16: =('Data Saham'!F16-'Data Saham'!F15)/'Data Saham'!F15 -> -0.075980392 | G16: =('Data Saham'!G16-'Data Saham'!G15)/'Data Saham'!G15 -> -0.033472803 | H16: =('Data Saham'!H16-'Data Saham'!H15)/'Data Saham'!H15 -> 0.027600849 | I16: =('Data Saham'!I16-'Data Saham'!I15)/'Data Saham'!I15 -> -0.0023584906 | ... AF16: =('Data Saham'!AF16-'Data Saham'!AF15)/'Data Saham'!AF15 -> -0.069620253
A17: 03/24/2025 | B17: =('Data Saham'!B17-'Data Saham'!B16)/'Data Saham'!B16 -> -0.015493322 | C17: =('Data Saham'!C17-'Data Saham'!C16)/'Data Saham'!C16 -> 0.0063291139 | D17: =('Data Saham'!D17-'Data Saham'!D16)/'Data Saham'!D16 -> -0.024324324 | E17: =('Data Saham'!E17-'Data Saham'!E16)/'Data Saham'!E16 -> 0.011337868 | F17: =('Data Saham'!F17-'Data Saham'!F16)/'Data Saham'!F16 -> -0.013262599 | G17: =('Data Saham'!G17-'Data Saham'!G16)/'Data Saham'!G16 -> 0.0086580087 | H17: =('Data Saham'!H17-'Data Saham'!H16)/'Data Saham'!H16 -> -0.030991736 | I17: =('Data Saham'!I17-'Data Saham'!I16)/'Data Saham'!I16 -> -0.014184397 | ... AF17: =('Data Saham'!AF17-'Data Saham'!AF16)/'Data Saham'!AF16 -> -0.020408163
A18: 03/25/2025 | B18: =('Data Saham'!B18-'Data Saham'!B17)/'Data Saham'!B17 -> 0.01207553 | C18: =('Data Saham'!C18-'Data Saham'!C17)/'Data Saham'!C17 -> 0.012578616 | D18: =('Data Saham'!D18-'Data Saham'!D17)/'Data Saham'!D17 -> 0.052631579 | E18: =('Data Saham'!E18-'Data Saham'!E17)/'Data Saham'!E17 -> 0.062780269 | F18: =('Data Saham'!F18-'Data Saham'!F17)/'Data Saham'!F17 -> 0.048387097 | G18: =('Data Saham'!G18-'Data Saham'!G17)/'Data Saham'!G17 -> 0.0042918455 | H18: =('Data Saham'!H18-'Data Saham'!H17)/'Data Saham'!H17 -> -0.0085287846 | I18: =('Data Saham'!I18-'Data Saham'!I17)/'Data Saham'!I17 -> -0.0047961631 | ... AF18: =('Data Saham'!AF18-'Data Saham'!AF17)/'Data Saham'!AF17 -> 0.034722222
A19: 03/26/2025 | B19: =('Data Saham'!B19-'Data Saham'!B18)/'Data Saham'!B18 -> 0.037965752 | C19: =('Data Saham'!C19-'Data Saham'!C18)/'Data Saham'!C18 -> 0.059006211 | D19: =('Data Saham'!D19-'Data Saham'!D18)/'Data Saham'!D18 -> 0.052631579 | E19: =('Data Saham'!E19-'Data Saham'!E18)/'Data Saham'!E18 -> 0.08649789 | F19: =('Data Saham'!F19-'Data Saham'!F18)/'Data Saham'!F18 -> 0.08974359 | G19: =('Data Saham'!G19-'Data Saham'!G18)/'Data Saham'!G18 -> 0.042735043 | H19: =('Data Saham'!H19-'Data Saham'!H18)/'Data Saham'!H18 -> 0.032258065 | I19: =('Data Saham'!I19-'Data Saham'!I18)/'Data Saham'!I18 -> 0.01686747 | ... AF19: =('Data Saham'!AF19-'Data Saham'!AF18)/'Data Saham'!AF18 -> 0.033557047
A20: 03/27/2025 | B20: =('Data Saham'!B20-'Data Saham'!B19)/'Data Saham'!B19 -> 0.0059112905 | C20: =('Data Saham'!C20-'Data Saham'!C19)/'Data Saham'!C19 -> -0.0029325513 | D20: =('Data Saham'!D20-'Data Saham'!D19)/'Data Saham'!D19 -> 0.0125 | E20: =('Data Saham'!E20-'Data Saham'!E19)/'Data Saham'!E19 -> 0.0097087379 | F20: =('Data Saham'!F20-'Data Saham'!F19)/'Data Saham'!F19 -> -0.0023529412 | G20: =('Data Saham'!G20-'Data Saham'!G19)/'Data Saham'!G19 -> -0.012295082 | H20: =('Data Saham'!H20-'Data Saham'!H19)/'Data Saham'!H19 -> 0.025 | I20: =('Data Saham'!I20-'Data Saham'!I19)/'Data Saham'!I19 -> -0.035545024 | ... AF20: =('Data Saham'!AF20-'Data Saham'!AF19)/'Data Saham'!AF19 -> -0.025974026
A21: 45873 | B21: =('Data Saham'!B21-'Data Saham'!B20)/'Data Saham'!B20 -> -0.07902166 | C21: =('Data Saham'!C21-'Data Saham'!C20)/'Data Saham'!C20 -> -0.085294118 | D21: =('Data Saham'!D21-'Data Saham'!D20)/'Data Saham'!D20 -> -0.10123457 | E21: =('Data Saham'!E21-'Data Saham'!E20)/'Data Saham'!E20 -> -0.10192308 | F21: =('Data Saham'!F21-'Data Saham'!F20)/'Data Saham'!F20 -> -0.049528302 | G21: =('Data Saham'!G21-'Data Saham'!G20)/'Data Saham'!G20 -> -0.049792531 | H21: =('Data Saham'!H21-'Data Saham'!H20)/'Data Saham'!H20 -> -0.089430894 | I21: =('Data Saham'!I21-'Data Saham'!I20)/'Data Saham'!I20 -> -0.046683047 | ... AF21: =('Data Saham'!AF21-'Data Saham'!AF20)/'Data Saham'!AF20 -> -0.04
A22: 45904 | B22: =('Data Saham'!B22-'Data Saham'!B21)/'Data Saham'!B21 -> -0.0046946869 | C22: =('Data Saham'!C22-'Data Saham'!C21)/'Data Saham'!C21 -> 0.019292605 | D22: =('Data Saham'!D22-'Data Saham'!D21)/'Data Saham'!D21 -> -0.0027472527 | E22: =('Data Saham'!E22-'Data Saham'!E21)/'Data Saham'!E21 -> 0.0085653105 | F22: =('Data Saham'!F22-'Data Saham'!F21)/'Data Saham'!F21 -> 0.0024813896 | G22: =('Data Saham'!G22-'Data Saham'!G21)/'Data Saham'!G21 -> 0.013100437 | H22: =('Data Saham'!H22-'Data Saham'!H21)/'Data Saham'!H21 -> 0.03125 | I22: =('Data Saham'!I22-'Data Saham'!I21)/'Data Saham'!I21 -> -0.012886598 | ... AF22: =('Data Saham'!AF22-'Data Saham'!AF21)/'Data Saham'!AF21 -> 0.034722222
A23: 45934 | B23: =('Data Saham'!B23-'Data Saham'!B22)/'Data Saham'!B22 -> 0.047927359 | C23: =('Data Saham'!C23-'Data Saham'!C22)/'Data Saham'!C22 -> 0.03785489 | D23: =('Data Saham'!D23-'Data Saham'!D22)/'Data Saham'!D22 -> 0.046831956 | E23: =('Data Saham'!E23-'Data Saham'!E22)/'Data Saham'!E22 -> 0.066878981 | F23: =('Data Saham'!F23-'Data Saham'!F22)/'Data Saham'!F22 -> 0.054455446 | G23: =('Data Saham'!G23-'Data Saham'!G22)/'Data Saham'!G22 -> 0.012931034 | H23: =('Data Saham'!H23-'Data Saham'!H22)/'Data Saham'!H22 -> 0.019480519 | I23: =('Data Saham'!I23-'Data Saham'!I22)/'Data Saham'!I22 -> 0.044386423 | ... AF23: =('Data Saham'!AF23-'Data Saham'!AF22)/'Data Saham'!AF22 -> 0.067114094
A24: 45965 | B24: =('Data Saham'!B24-'Data Saham'!B23)/'Data Saham'!B23 -> 0.0013127556 | C24: =('Data Saham'!C24-'Data Saham'!C23)/'Data Saham'!C23 -> 0.0060790274 | D24: =('Data Saham'!D24-'Data Saham'!D23)/'Data Saham'!D23 -> -0.044736842 | E24: =('Data Saham'!E24-'Data Saham'!E23)/'Data Saham'!E23 -> 0.014925373 | F24: =('Data Saham'!F24-'Data Saham'!F23)/'Data Saham'!F23 -> 0.030516432 | G24: =('Data Saham'!G24-'Data Saham'!G23)/'Data Saham'!G23 -> -0.0085106383 | H24: =('Data Saham'!H24-'Data Saham'!H23)/'Data Saham'!H23 -> 0 | I24: =('Data Saham'!I24-'Data Saham'!I23)/'Data Saham'!I23 -> -0.0075 | ... AF24: =('Data Saham'!AF24-'Data Saham'!AF23)/'Data Saham'!AF23 -> -0.0062893082
A25: 04/14/2025 | B25: =('Data Saham'!B25-'Data Saham'!B24)/'Data Saham'!B24 -> 0.016973187 | C25: =('Data Saham'!C25-'Data Saham'!C24)/'Data Saham'!C24 -> 0.01510574 | D25: =('Data Saham'!D25-'Data Saham'!D24)/'Data Saham'!D24 -> 0.016528926 | E25: =('Data Saham'!E25-'Data Saham'!E24)/'Data Saham'!E24 -> -0.068627451 | F25: =('Data Saham'!F25-'Data Saham'!F24)/'Data Saham'!F24 -> 0.036446469 | G25: =('Data Saham'!G25-'Data Saham'!G24)/'Data Saham'!G24 -> 0.042918455 | H25: =('Data Saham'!H25-'Data Saham'!H24)/'Data Saham'!H24 -> 0.04670913 | I25: =('Data Saham'!I25-'Data Saham'!I24)/'Data Saham'!I24 -> 0.040302267 | ... AF25: =('Data Saham'!AF25-'Data Saham'!AF24)/'Data Saham'!AF24 -> 0.063291139
A26: 04/15/2025 | B26: =('Data Saham'!B26-'Data Saham'!B25)/'Data Saham'!B25 -> 0.011487755 | C26: =('Data Saham'!C26-'Data Saham'!C25)/'Data Saham'!C25 -> 0.020833333 | D26: =('Data Saham'!D26-'Data Saham'!D25)/'Data Saham'!D25 -> 0 | E26: =('Data Saham'!E26-'Data Saham'!E25)/'Data Saham'!E25 -> -0.0084210526 | F26: =('Data Saham'!F26-'Data Saham'!F25)/'Data Saham'!F25 -> -0.059340659 | G26: =('Data Saham'!G26-'Data Saham'!G25)/'Data Saham'!G25 -> 0.0082304527 | H26: =('Data Saham'!H26-'Data Saham'!H25)/'Data Saham'!H25 -> -0.012170385 | I26: =('Data Saham'!I26-'Data Saham'!I25)/'Data Saham'!I25 -> 0.014527845 | ... AF26: =('Data Saham'!AF26-'Data Saham'!AF25)/'Data Saham'!AF25 -> 0.005952381
A27: 04/16/2025 | B27: =('Data Saham'!B27-'Data Saham'!B26)/'Data Saham'!B26 -> -0.0064625998 | C27: =('Data Saham'!C27-'Data Saham'!C26)/'Data Saham'!C26 -> -0.011661808 | D27: =('Data Saham'!D27-'Data Saham'!D26)/'Data Saham'!D26 -> -0.010840108 | E27: =('Data Saham'!E27-'Data Saham'!E26)/'Data Saham'!E26 -> -0.016985138 | F27: =('Data Saham'!F27-'Data Saham'!F26)/'Data Saham'!F26 -> -0.042056075 | G27: =('Data Saham'!G27-'Data Saham'!G26)/'Data Saham'!G26 -> 0.012244898 | H27: =('Data Saham'!H27-'Data Saham'!H26)/'Data Saham'!H26 -> -0.018480493 | I27: =('Data Saham'!I27-'Data Saham'!I26)/'Data Saham'!I26 -> -0.021479714 | ... AF27: =('Data Saham'!AF27-'Data Saham'!AF26)/'Data Saham'!AF26 -> -0.035502959
A28: 04/17/2025 | B28: =('Data Saham'!B28-'Data Saham'!B27)/'Data Saham'!B27 -> 0.0059718283 | C28: =('Data Saham'!C28-'Data Saham'!C27)/'Data Saham'!C27 -> 0.0029498525 | D28: =('Data Saham'!D28-'Data Saham'!D27)/'Data Saham'!D27 -> -0.002739726 | E28: =('Data Saham'!E28-'Data Saham'!E27)/'Data Saham'!E27 -> -0.0064794816 | F28: =('Data Saham'!F28-'Data Saham'!F27)/'Data Saham'!F27 -> -0.014634146 | G28: =('Data Saham'!G28-'Data Saham'!G27)/'Data Saham'!G27 -> 0.028225806 | H28: =('Data Saham'!H28-'Data Saham'!H27)/'Data Saham'!H27 -> -0.0062761506 | I28: =('Data Saham'!I28-'Data Saham'!I27)/'Data Saham'!I27 -> 0.034146341 | ... AF28: =('Data Saham'!AF28-'Data Saham'!AF27)/'Data Saham'!AF27 -> 0.030674847
A29: 04/21/2025 | B29: =('Data Saham'!B29-'Data Saham'!B28)/'Data Saham'!B28 -> 0.0011959735 | C29: =('Data Saham'!C29-'Data Saham'!C28)/'Data Saham'!C28 -> -0.023529412 | D29: =('Data Saham'!D29-'Data Saham'!D28)/'Data Saham'!D28 -> -0.0054945055 | E29: =('Data Saham'!E29-'Data Saham'!E28)/'Data Saham'!E28 -> 0.002173913 | F29: =('Data Saham'!F29-'Data Saham'!F28)/'Data Saham'!F28 -> -0.012376238 | G29: =('Data Saham'!G29-'Data Saham'!G28)/'Data Saham'!G28 -> 0.0078431373 | H29: =('Data Saham'!H29-'Data Saham'!H28)/'Data Saham'!H28 -> 0.0084210526 | I29: =('Data Saham'!I29-'Data Saham'!I28)/'Data Saham'!I28 -> -0.0047169811 | ... AF29: =('Data Saham'!AF29-'Data Saham'!AF28)/'Data Saham'!AF28 -> 0.005952381
A30: 04/22/2025 | B30: =('Data Saham'!B30-'Data Saham'!B29)/'Data Saham'!B29 -> 0.014319024 | C30: =('Data Saham'!C30-'Data Saham'!C29)/'Data Saham'!C29 -> 0.024096386 | D30: =('Data Saham'!D30-'Data Saham'!D29)/'Data Saham'!D29 -> 0.0027624309 | E30: =('Data Saham'!E30-'Data Saham'!E29)/'Data Saham'!E29 -> 0.023861171 | F30: =('Data Saham'!F30-'Data Saham'!F29)/'Data Saham'!F29 -> 0.0050125313 | G30: =('Data Saham'!G30-'Data Saham'!G29)/'Data Saham'!G29 -> -0.0077821012 | H30: =('Data Saham'!H30-'Data Saham'!H29)/'Data Saham'!H29 -> -0.010438413 | I30: =('Data Saham'!I30-'Data Saham'!I29)/'Data Saham'!I29 -> -0.0071090047 | ... AF30: =('Data Saham'!AF30-'Data Saham'!AF29)/'Data Saham'!AF29 -> 0
A31: 04/23/2025 | B31: =('Data Saham'!B31-'Data Saham'!B30)/'Data Saham'!B30 -> 0.014699607 | C31: =('Data Saham'!C31-'Data Saham'!C30)/'Data Saham'!C30 -> 0.026470588 | D31: =('Data Saham'!D31-'Data Saham'!D30)/'Data Saham'!D30 -> 0.035812672 | E31: =('Data Saham'!E31-'Data Saham'!E30)/'Data Saham'!E30 -> 0.038135593 | F31: =('Data Saham'!F31-'Data Saham'!F30)/'Data Saham'!F30 -> 0.034912718 | G31: =('Data Saham'!G31-'Data Saham'!G30)/'Data Saham'!G30 -> 0.031372549 | H31: =('Data Saham'!H31-'Data Saham'!H30)/'Data Saham'!H30 -> 0.016877637 | I31: =('Data Saham'!I31-'Data Saham'!I30)/'Data Saham'!I30 -> 0.021479714 | ... AF31: =('Data Saham'!AF31-'Data Saham'!AF30)/'Data Saham'!AF30 -> 0.01183432
A32: 04/24/2025 | B32: =('Data Saham'!B32-'Data Saham'!B31)/'Data Saham'!B31 -> -0.0031502567 | C32: =('Data Saham'!C32-'Data Saham'!C31)/'Data Saham'!C31 -> -0.028653295 | D32: =('Data Saham'!D32-'Data Saham'!D31)/'Data Saham'!D31 -> -0.0079787234 | E32: =('Data Saham'!E32-'Data Saham'!E31)/'Data Saham'!E31 -> -0.0020408163 | F32: =('Data Saham'!F32-'Data Saham'!F31)/'Data Saham'!F31 -> 0.0048192771 | G32: =('Data Saham'!G32-'Data Saham'!G31)/'Data Saham'!G31 -> 0 | H32: =('Data Saham'!H32-'Data Saham'!H31)/'Data Saham'!H31 -> -0.010373444 | I32: =('Data Saham'!I32-'Data Saham'!I31)/'Data Saham'!I31 -> 0.028037383 | ... AF32: =('Data Saham'!AF32-'Data Saham'!AF31)/'Data Saham'!AF31 -> 0.01754386
A33: 04/25/2025 | B33: =('Data Saham'!B33-'Data Saham'!B32)/'Data Saham'!B32 -> 0.0098949418 | C33: =('Data Saham'!C33-'Data Saham'!C32)/'Data Saham'!C32 -> 0.014749263 | D33: =('Data Saham'!D33-'Data Saham'!D32)/'Data Saham'!D32 -> 0.0026809651 | E33: =('Data Saham'!E33-'Data Saham'!E32)/'Data Saham'!E32 -> 0.0020449898 | F33: =('Data Saham'!F33-'Data Saham'!F32)/'Data Saham'!F32 -> 0.0071942446 | G33: =('Data Saham'!G33-'Data Saham'!G32)/'Data Saham'!G32 -> -0.011406844 | H33: =('Data Saham'!H33-'Data Saham'!H32)/'Data Saham'!H32 -> 0.018867925 | I33: =('Data Saham'!I33-'Data Saham'!I32)/'Data Saham'!I32 -> 0 | ... AF33: =('Data Saham'!AF33-'Data Saham'!AF32)/'Data Saham'!AF32 -> 0.063218391
A34: 04/28/2025 | B34: =('Data Saham'!B34-'Data Saham'!B33)/'Data Saham'!B33 -> 0.0065953777 | C34: =('Data Saham'!C34-'Data Saham'!C33)/'Data Saham'!C33 -> 0.020348837 | D34: =('Data Saham'!D34-'Data Saham'!D33)/'Data Saham'!D33 -> 0.026737968 | E34: =('Data Saham'!E34-'Data Saham'!E33)/'Data Saham'!E33 -> 0.0040816327 | F34: =('Data Saham'!F34-'Data Saham'!F33)/'Data Saham'!F33 -> -0.0023809524 | G34: =('Data Saham'!G34-'Data Saham'!G33)/'Data Saham'!G33 -> -0.015384615 | H34: =('Data Saham'!H34-'Data Saham'!H33)/'Data Saham'!H33 -> 0.0061728395 | I34: =('Data Saham'!I34-'Data Saham'!I33)/'Data Saham'!I33 -> 0 | ... AF34: =('Data Saham'!AF34-'Data Saham'!AF33)/'Data Saham'!AF33 -> -0.021621622
A35: 04/29/2025 | B35: =('Data Saham'!B35-'Data Saham'!B34)/'Data Saham'!B34 -> 0.0038837002 | C35: =('Data Saham'!C35-'Data Saham'!C34)/'Data Saham'!C34 -> -0.0056980057 | D35: =('Data Saham'!D35-'Data Saham'!D34)/'Data Saham'!D34 -> 0.0026041667 | E35: =('Data Saham'!E35-'Data Saham'!E34)/'Data Saham'!E34 -> 0.0040650407 | F35: =('Data Saham'!F35-'Data Saham'!F34)/'Data Saham'!F34 -> -0.011933174 | G35: =('Data Saham'!G35-'Data Saham'!G34)/'Data Saham'!G34 -> 0.01171875 | H35: =('Data Saham'!H35-'Data Saham'!H34)/'Data Saham'!H34 -> -0.018404908 | I35: =('Data Saham'!I35-'Data Saham'!I34)/'Data Saham'!I34 -> 0.022727273 | ... AF35: =('Data Saham'!AF35-'Data Saham'!AF34)/'Data Saham'!AF34 -> 0
A36: 04/30/2025 | B36: =('Data Saham'!B36-'Data Saham'!B35)/'Data Saham'!B35 -> 0.0026240614 | C36: =('Data Saham'!C36-'Data Saham'!C35)/'Data Saham'!C35 -> 0.011461318 | D36: =('Data Saham'!D36-'Data Saham'!D35)/'Data Saham'!D35 -> 0 | E36: =('Data Saham'!E36-'Data Saham'!E35)/'Data Saham'!E35 -> -0.010121457 | F36: =('Data Saham'!F36-'Data Saham'!F35)/'Data Saham'!F35 -> 0.0096618357 | G36: =('Data Saham'!G36-'Data Saham'!G35)/'Data Saham'!G35 -> 0.019305019 | H36: =('Data Saham'!H36-'Data Saham'!H35)/'Data Saham'!H35 -> 0 | I36: =('Data Saham'!I36-'Data Saham'!I35)/'Data Saham'!I35 -> 0.0088888889 | ... AF36: =('Data Saham'!AF36-'Data Saham'!AF35)/'Data Saham'!AF35 -> 0.016574586
A37: 45693 | B37: =('Data Saham'!B37-'Data Saham'!B36)/'Data Saham'!B36 -> 0.0072323805 | C37: =('Data Saham'!C37-'Data Saham'!C36)/'Data Saham'!C36 -> 0.016997167 | D37: =('Data Saham'!D37-'Data Saham'!D36)/'Data Saham'!D36 -> 0.0077922078 | E37: =('Data Saham'!E37-'Data Saham'!E36)/'Data Saham'!E36 -> 0.014314928 | F37: =('Data Saham'!F37-'Data Saham'!F36)/'Data Saham'!F36 -> 0.004784689 | G37: =('Data Saham'!G37-'Data Saham'!G36)/'Data Saham'!G36 -> 0.015151515 | H37: =('Data Saham'!H37-'Data Saham'!H36)/'Data Saham'!H36 -> -0.0020833333 | I37: =('Data Saham'!I37-'Data Saham'!I36)/'Data Saham'!I36 -> -0.030837004 | ... AF37: =('Data Saham'!AF37-'Data Saham'!AF36)/'Data Saham'!AF36 -> 0.010869565
A38: 45782 | B38: =('Data Saham'!B38-'Data Saham'!B37)/'Data Saham'!B37 -> 0.0023797891 | C38: =('Data Saham'!C38-'Data Saham'!C37)/'Data Saham'!C37 -> 0 | D38: =('Data Saham'!D38-'Data Saham'!D37)/'Data Saham'!D37 -> -0.0051546392 | E38: =('Data Saham'!E38-'Data Saham'!E37)/'Data Saham'!E37 -> 0.0040322581 | F38: =('Data Saham'!F38-'Data Saham'!F37)/'Data Saham'!F37 -> 0.0023809524 | G38: =('Data Saham'!G38-'Data Saham'!G37)/'Data Saham'!G37 -> 0.0074626866 | H38: =('Data Saham'!H38-'Data Saham'!H37)/'Data Saham'!H37 -> -0.0020876827 | I38: =('Data Saham'!I38-'Data Saham'!I37)/'Data Saham'!I37 -> 0.018181818 | ... AF38: =('Data Saham'!AF38-'Data Saham'!AF37)/'Data Saham'!AF37 -> 0.021505376
A39: 45813 | B39: =('Data Saham'!B39-'Data Saham'!B38)/'Data Saham'!B38 -> 0.009697085 | C39: =('Data Saham'!C39-'Data Saham'!C38)/'Data Saham'!C38 -> 0.0055710306 | D39: =('Data Saham'!D39-'Data Saham'!D38)/'Data Saham'!D38 -> 0.0051813472 | E39: =('Data Saham'!E39-'Data Saham'!E38)/'Data Saham'!E38 -> 0 | F39: =('Data Saham'!F39-'Data Saham'!F38)/'Data Saham'!F38 -> -0.0071258907 | G39: =('Data Saham'!G39-'Data Saham'!G38)/'Data Saham'!G38 -> -0.0074074074 | H39: =('Data Saham'!H39-'Data Saham'!H38)/'Data Saham'!H38 -> -0.0062761506 | I39: =('Data Saham'!I39-'Data Saham'!I38)/'Data Saham'!I38 -> 0.0066964286 | ... AF39: =('Data Saham'!AF39-'Data Saham'!AF38)/'Data Saham'!AF38 -> 0
A40: 45843 | B40: =('Data Saham'!B40-'Data Saham'!B39)/'Data Saham'!B39 -> 0.0040633789 | C40: =('Data Saham'!C40-'Data Saham'!C39)/'Data Saham'!C39 -> 0.0055401662 | D40: =('Data Saham'!D40-'Data Saham'!D39)/'Data Saham'!D39 -> 0.0077319588 | E40: =('Data Saham'!E40-'Data Saham'!E39)/'Data Saham'!E39 -> -0.0060240964 | F40: =('Data Saham'!F40-'Data Saham'!F39)/'Data Saham'!F39 -> -0.004784689 | G40: =('Data Saham'!G40-'Data Saham'!G39)/'Data Saham'!G39 -> -0.02238806 | H40: =('Data Saham'!H40-'Data Saham'!H39)/'Data Saham'!H39 -> 0.016842105 | I40: =('Data Saham'!I40-'Data Saham'!I39)/'Data Saham'!I39 -> -0.017738359 | ... AF40: =('Data Saham'!AF40-'Data Saham'!AF39)/'Data Saham'!AF39 -> 0.036842105
...

Sheet Korelasi
B1: BBCA | C1: BBRI | D1: BMRI | E1: BBNI | F1: TLKM | G1: ASII | H1: ICBP | I1: INDF | J1: ADRO | K1: ITMG | L1: ANTM | M1: MDKA | N1: PGAS | O1: TOWR | P1: EXCL | Q1: KLBF | R1: CPIN | S1: JPFA | T1: SMGR | U1: UNTR | V1: BRPT | W1: AKRA | X1: AMRT | Y1: ACES | Z1: MAPI | AA1: GOTO | AB1: BUKA | AC1: SMRA | AD1: PWON | AE1: CTRA
A2: BBCA | B2: 1
A3: BBRI | B3: 0.61320874 | C3: 1
A4: BMRI | B4: 0.6083107 | C4: 0.66638713 | D4: 1
A5: BBNI | B5: 0.55972611 | C5: 0.65229944 | D5: 0.65476155 | E5: 1
A6: TLKM | B6: 0.42859283 | C6: 0.30947217 | D6: 0.33728852 | E6: 0.25365075 | F6: 1
A7: ASII | B7: 0.31482483 | C7: 0.32391284 | D7: 0.22867785 | E7: 0.30796412 | F7: 0.12889082 | G7: 1
A8: ICBP | B8: 0.25888129 | C8: 0.16894063 | D8: 0.11683591 | E8: 0.1867646 | F8: 0.17329508 | G8: 0.086478012 | H8: 1
A9: INDF | B9: 0.17596563 | C9: 0.15968326 | D9: 0.088011331 | E9: 0.18519878 | F9: 0.14922204 | G9: 0.10890882 | H9: 0.2857051 | I9: 1
A10: ADRO | B10: 0.31915114 | C10: 0.32082361 | D10: 0.29108506 | E10: 0.21626733 | F10: 0.25302271 | G10: 0.20953256 | H10: 0.16253136 | I10: 0.063383144 | J10: 1
A11: ITMG | B11: 0.3042925 | C11: 0.26119941 | D11: 0.21004756 | E11: 0.27559966 | F11: 0.09331505 | G11: 0.22692028 | H11: 0.16270583 | I11: 0.041481257 | J11: 0.25845552 | K11: 1
A12: ANTM | B12: 0.12164443 | C12: 0.076041213 | D12: 0.013781309 | E12: -0.0072609545 | F12: 0.12136321 | G12: 0.11890222 | H12: 0.11103027 | I12: 0.038305986 | J12: 0.31644354 | K12: 0.13427409 | L12: 1
A13: MDKA | B13: 0.16109978 | C13: 0.07566552 | D13: 0.12046228 | E13: 0.11428679 | F13: 0.093038098 | G13: 0.22813418 | H13: 0.22404599 | I13: 0.16519796 | J13: 0.37144742 | K13: 0.21159391 | L13: 0.57417348 | M13: 1
A14: PGAS | B14: 0.27556296 | C14: 0.28107978 | D14: 0.31957483 | E14: 0.28119421 | F14: 0.26683852 | G14: 0.2255658 | H14: 0.17207095 | I14: 0.11541881 | J14: 0.32121719 | K14: 0.21559172 | L14: 0.20848244 | M14: 0.22051122 | N14: 1
A15: TOWR | B15: 0.30932054 | C15: 0.31098446 | D15: 0.24676909 | E15: 0.21030698 | F15: 0.17306722 | G15: 0.21396937 | H15: 0.28471742 | I15: 0.020691113 | J15: 0.26036611 | K15: 0.27510558 | L15: 0.22583306 | M15: 0.27895292 | N15: 0.18265868 | O15: 1
A16: EXCL | B16: 0.11677029 | C16: 0.18477847 | D16: 0.1347784 | E16: 0.097949655 | F16: 0.31031624 | G16: 0.094149462 | H16: 0.081463924 | I16: 0.0164922 | J16: 0.18105337 | K16: 0.1026179 | L16: 0.14357348 | M16: 0.089805106 | N16: 0.22299811 | O16: 0.17140512 | P16: 1
A17: KLBF | B17: 0.23676599 | C17: 0.20923883 | D17: 0.19750546 | E17: 0.28679211 | F17: 0.1527762 | G17: 0.15267383 | H17: 0.40134943 | I17: 0.16354715 | J17: 0.20066704 | K17: 0.1554733 | L17: 0.14235297 | M17: 0.1473319 | N17: 0.17952328 | O17: 0.16496423 | P17: 0.041269669 | Q17: 1
A18: CPIN | B18: 0.24205425 | C18: 0.25430901 | D18: 0.13673442 | E18: 0.27188449 | F18: 0.179065 | G18: 0.27592296 | H18: 0.30715478 | I18: 0.28336007 | J18: 0.089444354 | K18: 0.18882997 | L18: 0.13086177 | M18: 0.11393042 | N18: 0.079594577 | O18: 0.22836816 | P18: 0.10484145 | Q18: 0.21116513 | R18: 1
A19: JPFA | B19: 0.078536528 | C19: 0.1631591 | D19: 0.087521499 | E19: 0.20057354 | F19: 0.12707533 | G19: 0.13157625 | H19: 0.088937047 | I19: 0.065183182 | J19: 0.062630722 | K19: 0.12697147 | L19: -0.0036535424 | M19: 0.13531475 | N19: 0.12935792 | O19: 0.16372206 | P19: 0.066085555 | Q19: 0.12418045 | R19: 0.34068083 | S19: 1
A20: SMGR | B20: 0.36615677 | C20: 0.33995485 | D20: 0.32694862 | E20: 0.38233605 | F20: 0.30082927 | G20: 0.22338931 | H20: 0.26856353 | I20: 0.16501215 | J20: 0.23826479 | K20: 0.30863002 | L20: 0.11289792 | M20: 0.19090277 | N20: 0.25977027 | O20: 0.17324418 | P20: 0.14649111 | Q20: 0.14404441 | R20: 0.1948757 | S20: 0.1355434 | T20: 1
A21: UNTR | B21: 0.33047604 | C21: 0.28911463 | D21: 0.24558449 | E21: 0.24041324 | F21: 0.15486461 | G21: 0.44337668 | H21: 0.20262244 | I21: 0.056226249 | J21: 0.28081623 | K21: 0.25411858 | L21: 0.28921794 | M21: 0.27593839 | N21: 0.14738791 | O21: 0.22375946 | P21: 0.2286192 | Q21: 0.18174015 | R21: 0.24623522 | S21: 0.1489168 | T21: 0.23316548 | U21: 1
A22: BRPT | B22: 0.1302875 | C22: 0.18008007 | D22: 0.11794029 | E22: 0.056770541 | F22: 0.1318139 | G22: 0.076035824 | H22: 0.098051056 | I22: 0.090483589 | J22: 0.1391771 | K22: 0.14918468 | L22: 0.16695752 | M22: 0.20948715 | N22: 0.11327064 | O22: 0.10885631 | P22: 0.29484351 | Q22: 0.094952175 | R22: 0.031294319 | S22: 0.13974212 | T22: 0.078045569 | U22: 0.19957672 | V22: 1
A23: AKRA | B23: 0.29305581 | C23: 0.33418407 | D23: 0.31912504 | E23: 0.29659872 | F23: 0.17265683 | G23: 0.22586088 | H23: 0.24620616 | I23: 0.22537499 | J23: 0.17581768 | K23: 0.17271262 | L23: 0.24709764 | M23: 0.33507369 | N23: 0.1871594 | O23: 0.28423162 | P23: 0.19456299 | Q23: 0.20235695 | R23: 0.11058003 | S23: 0.1693457 | T23: 0.22521396 | U23: 0.32737757 | V23: 0.18624265 | W23: 1
A24: AMRT | B24: 0.25026694 | C24: 0.17800615 | D24: 0.31405475 | E24: 0.3509611 | F24: 0.23885995 | G24: 0.066469517 | H24: 0.25881329 | I24: 0.20539076 | J24: 0.10673928 | K24: 0.12721002 | L24: 0.052359417 | M24: 0.12473661 | N24: 0.15967068 | O24: 0.1884973 | P24: 0.083034095 | Q24: 0.20369379 | R24: 0.20477385 | S24: 0.14986846 | T24: 0.15960163 | U24: 0.14183173 | V24: 0.1491873 | W24: 0.27633173 | X24: 1
A25: ACES | B25: 0.35195768 | C25: 0.37702893 | D25: 0.30673186 | E25: 0.36091526 | F25: 0.27061028 | G25: 0.23465894 | H25: 0.20350762 | I25: 0.14412693 | J25: 0.23065222 | K25: 0.24490816 | L25: 0.13509359 | M25: 0.15812415 | N25: 0.22682745 | O25: 0.24391274 | P25: 0.12287881 | Q25: 0.094736064 | R25: 0.28102826 | S25: 0.19023152 | T25: 0.35486849 | U25: 0.2695737 | V25: 0.18966799 | W25: 0.24948691 | X25: 0.28082245 | Y25: 1
A26: MAPI | B26: 0.34437997 | C26: 0.31858208 | D26: 0.29434405 | E26: 0.26421136 | F26: 0.24780371 | G26: 0.11189966 | H26: 0.44678282 | I26: 0.21907141 | J26: 0.23636964 | K26: 0.26443587 | L26: 0.22920438 | M26: 0.25218583 | N26: 0.25208143 | O26: 0.28297907 | P26: 0.16219767 | Q26: 0.27929566 | R26: 0.2837336 | S26: 0.11818595 | T26: 0.26247028 | U26: 0.29564815 | V26: 0.25523658 | W26: 0.3970947 | X26: 0.28682572 | Y26: 0.36511013 | Z26: 1
A27: GOTO | B27: 0.24545558 | C27: 0.21663211 | D27: 0.23177986 | E27: 0.19940815 | F27: 0.18697411 | G27: 0.10728258 | H27: 0.2390783 | I27: 0.15123639 | J27: 0.18759208 | K27: 0.16808325 | L27: 0.15457372 | M27: 0.24037548 | N27: 0.10590609 | O27: 0.13143983 | P27: 0.17198488 | Q27: 0.094828247 | R27: 0.28257021 | S27: 0.1684329 | T27: 0.18225059 | U27: 0.1953473 | V27: 0.11494485 | W27: 0.25211039 | X27: 0.17244055 | Y27: 0.27013165 | Z27: 0.33774413 | AA27: 1
A28: BUKA | B28: 0.218377 | C28: 0.18032378 | D28: 0.19458521 | E28: 0.1641774 | F28: 0.14480865 | G28: 0.18782049 | H28: 0.2081997 | I28: 0.101866 | J28: 0.19992265 | K28: 0.13372545 | L28: 0.16668028 | M28: 0.24344488 | N28: 0.16865538 | O28: 0.21734613 | P28: 0.22056494 | Q28: 0.11357569 | R28: 0.17546555 | S28: 0.10468115 | T28: 0.21296662 | U28: 0.32688978 | V28: 0.25753113 | W28: 0.18408909 | X28: 0.06263875 | Y28: 0.19592253 | Z28: 0.22928215 | AA28: 0.23668988 | AB28: 1
A29: SMRA | B29: 0.47368324 | C29: 0.40710683 | D29: 0.35419075 | E29: 0.39766402 | F29: 0.22976492 | G29: 0.28626412 | H29: 0.28359878 | I29: 0.14962515 | J29: 0.3539346 | K29: 0.28310491 | L29: 0.27803815 | M29: 0.3659583 | N29: 0.22506503 | O29: 0.38560584 | P29: 0.17321761 | Q29: 0.23665787 | R29: 0.29674071 | S29: 0.18570454 | T29: 0.36452718 | U29: 0.32140029 | V29: 0.16503644 | W29: 0.34217744 | X29: 0.22921415 | Y29: 0.33348987 | Z29: 0.3739428 | AA29: 0.3041949 | AB29: 0.32185981 | AC29: 1
A30: PWON | B30: 0.41877849 | C30: 0.39030198 | D30: 0.32843055 | E30: 0.43440927 | F30: 0.21661428 | G30: 0.21996269 | H30: 0.22966232 | I30: 0.21295441 | J30: 0.30163377 | K30: 0.29943625 | L30: 0.23519144 | M30: 0.254329 | N30: 0.22458755 | O30: 0.33643047 | P30: 0.091927517 | Q30: 0.2164839 | R30: 0.24118455 | S30: 0.10139759 | T30: 0.37011506 | U30: 0.28733183 | V30: 0.1332801 | W30: 0.2946996 | X30: 0.21573703 | Y30: 0.40835365 | Z30: 0.36654357 | AA30: 0.23970759 | AB30: 0.23940579 | AC30: 0.55042266 | AD30: 1
A31: CTRA | B31: 0.041430471 | C31: 0.016845058 | D31: -0.021055159 | E31: 0.037653272 | F31: -0.0060789303 | G31: -0.093018582 | H31: 0.084822043 | I31: 0.0041051392 | J31: -0.047361462 | K31: 0.03418063 | L31: 0.062385398 | M31: -0.016396149 | N31: -0.15815294 | O31: -0.019506682 | P31: -0.037379828 | Q31: 0.00044038951 | R31: 0.079730216 | S31: -0.081243927 | T31: 0.097196929 | U31: -0.015385059 | V31: -0.024445407 | W31: 0.14937146 | X31: 0.053902951 | Y31: -0.066259579 | Z31: -0.0014622755 | AA31: -0.04224844 | AB31: -0.069490165 | AC31: 0.023249729 | AD31: 0.0053062884 | AE31: 1
C37: =MIN(B31:AE31) -> -0.15815294

Sheet Return Estimasi
A1: Date | B1: IHSG | C1: BBCA | D1: BBRI | E1: BMRI | F1: BBNI | G1: TLKM | H1: ASII | I1: ICBP | J1: INDF | K1: ADRO | L1: ITMG | M1: ANTM | N1: MDKA | O1: PGAS | P1: TOWR | Q1: EXCL | R1: KLBF | S1: CPIN | T1: JPFA | U1: SMGR | V1: UNTR | W1: BRPT | X1: AKRA | Y1: AMRT | Z1: ACES | AA1: MAPI | AB1: GOTO | AC1: BUKA | AD1: SMRA | AE1: PWON | AF1: CTRA
A2: 45719
A3: 45750 | C3: =Perhitungan!B$4+Perhitungan!B$3*Return!$B3 -> -0.01998709 | D3: =Perhitungan!C$4+Perhitungan!C$3*Return!$B3 -> -0.019821933 | E3: =Perhitungan!D$4+Perhitungan!D$3*Return!$B3 -> -0.02082729 | F3: =Perhitungan!E$4+Perhitungan!E$3*Return!$B3 -> -0.018202282 | G3: =Perhitungan!F$4+Perhitungan!F$3*Return!$B3 -> -0.0176245 | H3: =Perhitungan!G$4+Perhitungan!G$3*Return!$B3 -> -0.013917988 | I3: =Perhitungan!H$4+Perhitungan!H$3*Return!$B3 -> -0.010917941 | J3: =Perhitungan!I$4+Perhitungan!I$3*Return!$B3 -> -0.006195768 | ... AF3: =Perhitungan!AE$4+Perhitungan!AE$3*Return!$B3 -> 17.28048
A4: 45780 | C4: =Perhitungan!B$4+Perhitungan!B$3*Return!$B4 -> 0.018689833 | D4: =Perhitungan!C$4+Perhitungan!C$3*Return!$B4 -> 0.024456126 | E4: =Perhitungan!D$4+Perhitungan!D$3*Return!$B4 -> 0.023237961 | F4: =Perhitungan!E$4+Perhitungan!E$3*Return!$B4 -> 0.019935737 | G4: =Perhitungan!F$4+Perhitungan!F$3*Return!$B4 -> 0.022937629 | H4: =Perhitungan!G$4+Perhitungan!G$3*Return!$B4 -> 0.01637484 | I4: =Perhitungan!H$4+Perhitungan!H$3*Return!$B4 -> 0.0081649372 | J4: =Perhitungan!I$4+Perhitungan!I$3*Return!$B4 -> 0.0067386093 | ... AF4: =Perhitungan!AE$4+Perhitungan!AE$3*Return!$B4 -> 16.014519
A5: 45811 | C5: =Perhitungan!B$4+Perhitungan!B$3*Return!$B5 -> 0.0097304605 | D5: =Perhitungan!C$4+Perhitungan!C$3*Return!$B5 -> 0.014199271 | E5: =Perhitungan!D$4+Perhitungan!D$3*Return!$B5 -> 0.013030402 | F5: =Perhitungan!E$4+Perhitungan!E$3*Return!$B5 -> 0.0111012 | G5: =Perhitungan!F$4+Perhitungan!F$3*Return!$B5 -> 0.013541556 | H5: =Perhitungan!G$4+Perhitungan!G$3*Return!$B5 -> 0.0093576139 | I5: =Perhitungan!H$4+Perhitungan!H$3*Return!$B5 -> 0.0037444561 | J5: =Perhitungan!I$4+Perhitungan!I$3*Return!$B5 -> 0.0037424067 | ... AF5: =Perhitungan!AE$4+Perhitungan!AE$3*Return!$B5 -> 16.307774
A6: 45841 | C6: =Perhitungan!B$4+Perhitungan!B$3*Return!$B6 -> 0.00071670706 | D6: =Perhitungan!C$4+Perhitungan!C$3*Return!$B6 -> 0.0038801585 | E6: =Perhitungan!D$4+Perhitungan!D$3*Return!$B6 -> 0.0027608853 | F6: =Perhitungan!E$4+Perhitungan!E$3*Return!$B6 -> 0.0022130396 | G6: =Perhitungan!F$4+Perhitungan!F$3*Return!$B6 -> 0.0040884504 | H6: =Perhitungan!G$4+Perhitungan!G$3*Return!$B6 -> 0.0022977946 | I6: =Perhitungan!H$4+Perhitungan!H$3*Return!$B6 -> -0.00070285647 | J6: =Perhitungan!I$4+Perhitungan!I$3*Return!$B6 -> 0.00072801777 | ... AF6: =Perhitungan!AE$4+Perhitungan!AE$3*Return!$B6 -> 16.60281
A7: 45933 | C7: =Perhitungan!B$4+Perhitungan!B$3*Return!$B7 -> -0.0065307996 | D7: =Perhitungan!C$4+Perhitungan!C$3*Return!$B7 -> -0.0044169217 | E7: =Perhitungan!D$4+Perhitungan!D$3*Return!$B7 -> -0.0054963176 | F7: =Perhitungan!E$4+Perhitungan!E$3*Return!$B7 -> -0.0049334841 | G7: =Perhitungan!F$4+Perhitungan!F$3*Return!$B7 -> -0.0035123171 | H7: =Perhitungan!G$4+Perhitungan!G$3*Return!$B7 -> -0.0033786516 | I7: =Perhitungan!H$4+Perhitungan!H$3*Return!$B7 -> -0.0042787172 | J7: =Perhitungan!I$4+Perhitungan!I$3*Return!$B7 -> -0.0016957011 | ... AF7: =Perhitungan!AE$4+Perhitungan!AE$3*Return!$B7 -> 16.840033
A8: 45964 | C8: =Perhitungan!B$4+Perhitungan!B$3*Return!$B8 -> -0.0084556076 | D8: =Perhitungan!C$4+Perhitungan!C$3*Return!$B8 -> -0.0066204776 | E8: =Perhitungan!D$4+Perhitungan!D$3*Return!$B8 -> -0.0076892828 | F8: =Perhitungan!E$4+Perhitungan!E$3*Return!$B8 -> -0.0068314728 | G8: =Perhitungan!F$4+Perhitungan!F$3*Return!$B8 -> -0.0055309448 | H8: =Perhitungan!G$4+Perhitungan!G$3*Return!$B8 -> -0.0048862141 | I8: =Perhitungan!H$4+Perhitungan!H$3*Return!$B8 -> -0.0052284018 | J8: =Perhitungan!I$4+Perhitungan!I$3*Return!$B8 -> -0.0023393974 | ... AF8: =Perhitungan!AE$4+Perhitungan!AE$3*Return!$B8 -> 16.903035
A9: 45994 | C9: =Perhitungan!B$4+Perhitungan!B$3*Return!$B9 -> 0.014001704 | D9: =Perhitungan!C$4+Perhitungan!C$3*Return!$B9 -> 0.01908907 | E9: =Perhitungan!D$4+Perhitungan!D$3*Return!$B9 -> 0.0178967 | F9: =Perhitungan!E$4+Perhitungan!E$3*Return!$B9 -> 0.015312931 | G9: =Perhitungan!F$4+Perhitungan!F$3*Return!$B9 -> 0.01802099 | H9: =Perhitungan!G$4+Perhitungan!G$3*Return!$B9 -> 0.012702969 | I9: =Perhitungan!H$4+Perhitungan!H$3*Return!$B9 -> 0.005851853 | J9: =Perhitungan!I$4+Perhitungan!I$3*Return!$B9 -> 0.0051708006 | ... AF9: =Perhitungan!AE$4+Perhitungan!AE$3*Return!$B9 -> 16.167969
A10: 03/13/2025 | C10: =Perhitungan!B$4+Perhitungan!B$3*Return!$B10 -> -0.0039099889 | D10: =Perhitungan!C$4+Perhitungan!C$3*Return!$B10 -> -0.0014165689 | E10: =Perhitungan!D$4+Perhitungan!D$3*Return!$B10 -> -0.0025103851 | F10: =Perhitungan!E$4+Perhitungan!E$3*Return!$B10 -> -0.0023491904 | G10: =Perhitungan!F$4+Perhitungan!F$3*Return!$B10 -> -0.00076376176 | H10: =Perhitungan!G$4+Perhitungan!G$3*Return!$B10 -> -0.0013259607 | I10: =Perhitungan!H$4+Perhitungan!H$3*Return!$B10 -> -0.0029856305 | J10: =Perhitungan!I$4+Perhitungan!I$3*Return!$B10 -> -0.00081924676 | ... AF10: =Perhitungan!AE$4+Perhitungan!AE$3*Return!$B10 -> 16.75425
A11: 03/14/2025 | C11: =Perhitungan!B$4+Perhitungan!B$3*Return!$B11 -> -0.018669171 | D11: =Perhitungan!C$4+Perhitungan!C$3*Return!$B11 -> -0.018313155 | E11: =Perhitungan!D$4+Perhitungan!D$3*Return!$B11 -> -0.019325763 | F11: =Perhitungan!E$4+Perhitungan!E$3*Return!$B11 -> -0.016902726 | G11: =Perhitungan!F$4+Perhitungan!F$3*Return!$B11 -> -0.016242342 | H11: =Perhitungan!G$4+Perhitungan!G$3*Return!$B11 -> -0.012885757 | I11: =Perhitungan!H$4+Perhitungan!H$3*Return!$B11 -> -0.010267691 | J11: =Perhitungan!I$4+Perhitungan!I$3*Return!$B11 -> -0.005755028 | ... AF11: =Perhitungan!AE$4+Perhitungan!AE$3*Return!$B11 -> 17.237343
A12: 03/17/2025 | C12: =Perhitungan!B$4+Perhitungan!B$3*Return!$B12 -> -0.007397675 | D12: =Perhitungan!C$4+Perhitungan!C$3*Return!$B12 -> -0.0054093368 | E12: =Perhitungan!D$4+Perhitungan!D$3*Return!$B12 -> -0.0064839629 | F12: =Perhitungan!E$4+Perhitungan!E$3*Return!$B12 -> -0.0057882809 | G12: =Perhitungan!F$4+Perhitungan!F$3*Return!$B12 -> -0.0044214461 | H12: =Perhitungan!G$4+Perhitungan!G$3*Return!$B12 -> -0.0040576122 | I12: =Perhitungan!H$4+Perhitungan!H$3*Return!$B12 -> -0.0047064265 | J12: =Perhitungan!I$4+Perhitungan!I$3*Return!$B12 -> -0.0019856024 | ... AF12: =Perhitungan!AE$4+Perhitungan!AE$3*Return!$B12 -> 16.868407
A13: 03/18/2025 | C13: =Perhitungan!B$4+Perhitungan!B$3*Return!$B13 -> -0.034629136 | D13: =Perhitungan!C$4+Perhitungan!C$3*Return!$B13 -> -0.036584419 | E13: =Perhitungan!D$4+Perhitungan!D$3*Return!$B13 -> -0.037509212 | F13: =Perhitungan!E$4+Perhitungan!E$3*Return!$B13 -> -0.032640313 | G13: =Perhitungan!F$4+Perhitungan!F$3*Return!$B13 -> -0.032980234 | H13: =Perhitungan!G$4+Perhitungan!G$3*Return!$B13 -> -0.02538604 | I13: =Perhitungan!H$4+Perhitungan!H$3*Return!$B13 -> -0.018142207 | J13: =Perhitungan!I$4+Perhitungan!I$3*Return!$B13 -> -0.011092376 | ... AF13: =Perhitungan!AE$4+Perhitungan!AE$3*Return!$B13 -> 17.75974
A14: 03/19/2025 | C14: =Perhitungan!B$4+Perhitungan!B$3*Return!$B14 -> 0.010544374 | D14: =Perhitungan!C$4+Perhitungan!C$3*Return!$B14 -> 0.015131055 | E14: =Perhitungan!D$4+Perhitungan!D$3*Return!$B14 -> 0.013957707 | F14: =Perhitungan!E$4+Perhitungan!E$3*Return!$B14 -> 0.011903773 | G14: =Perhitungan!F$4+Perhitungan!F$3*Return!$B14 -> 0.014395142 | H14: =Perhitungan!G$4+Perhitungan!G$3*Return!$B14 -> 0.0099950936 | I14: =Perhitungan!H$4+Perhitungan!H$3*Return!$B14 -> 0.0041460346 | J14: =Perhitungan!I$4+Perhitungan!I$3*Return!$B14 -> 0.0040145967 | ... AF14: =Perhitungan!AE$4+Perhitungan!AE$3*Return!$B14 -> 16.281134
A15: 03/20/2025 | C15: =Perhitungan!B$4+Perhitungan!B$3*Return!$B15 -> 0.0078888878 | D15: =Perhitungan!C$4+Perhitungan!C$3*Return!$B15 -> 0.012091004 | E15: =Perhitungan!D$4+Perhitungan!D$3*Return!$B15 -> 0.010932268 | F15: =Perhitungan!E$4+Perhitungan!E$3*Return!$B15 -> 0.0092852869 | G15: =Perhitungan!F$4+Perhitungan!F$3*Return!$B15 -> 0.01161022 | H15: =Perhitungan!G$4+Perhitungan!G$3*Return!$B15 -> 0.0079152436 | I15: =Perhitungan!H$4+Perhitungan!H$3*Return!$B15 -> 0.0028358391 | J15: =Perhitungan!I$4+Perhitungan!I$3*Return!$B15 -> 0.003126546 | ... AF15: =Perhitungan!AE$4+Perhitungan!AE$3*Return!$B15 -> 16.368052
